<?xml version="1.0" ?>
<robot name="balo">
  <link name="bottomshell_1">
    <visual name="bottomshell_1_visual">
      <origin xyz="0 0 0" rpy="0 0 0"/>
      <geometry>
        <mesh filename="meshes/bottomshell_1.stl"/>
      </geometry>
      <material name="bottomshell_1-material">
        <color rgba="0 0 1 1"/>
      </material>
    </visual>
    <collision name="bottomshell_1_collision">
      <origin xyz="0 0 0" rpy="0 0 0"/>
      <geometry>
        <mesh filename="meshes/bottomshell_1.stl"/>
      </geometry>
    </collision>
    <inertial>
      <mass value="0.044489363"/>
      <inertia ixx="5.2768136e-05" iyy="6.083524e-05" izz="6.130275e-05" ixy="-5.078488e-10" ixz="-4.6418392e-10" iyz="-1.7256708e-05"/>
      <origin xyz="0 0 0" rpy="0 0 0"/>
    </inertial>
  </link>
  <link name="topshell_1">
    <visual name="topshell_1_visual">
      <origin xyz="0 0 0" rpy="0 0 0"/>
      <geometry>
        <mesh filename="meshes/topshell_1.stl"/>
      </geometry>
      <material name="topshell_1-material">
        <color rgba="0 1 1 1"/>
      </material>
    </visual>
    <collision name="topshell_1_collision">
      <origin xyz="0 0 0" rpy="0 0 0"/>
      <geometry>
        <mesh filename="meshes/topshell_1.stl"/>
      </geometry>
    </collision>
    <inertial>
      <mass value="0.044489489"/>
      <inertia ixx="5.276822e-05" iyy="4.4182551e-05" izz="7.7956283e-05" ixy="-1.4831019e-10" ixz="-3.3978567e-10" iyz="-3.5599247e-06"/>
      <origin xyz="-3.3424056e-07 -0.0017103253 -0.02659475" rpy="0 0 0"/>
    </inertial>
  </link>
  <link name="pendulum_1">
    <visual name="pendulum_1_visual">
      <origin xyz="0 0 0" rpy="0 0 0"/>
      <geometry>
        <mesh filename="meshes/pendulum_1.stl"/>
      </geometry>
      <material name="pendulum_1-material">
        <color rgba="0 0 1 1"/>
      </material>
    </visual>
    <collision name="pendulum_1_collision">
      <origin xyz="0 0 0" rpy="0 0 0"/>
      <geometry>
        <mesh filename="meshes/pendulum_1.stl"/>
      </geometry>
    </collision>
    <inertial>
      <mass value="0"/>
      <inertia ixx="0" iyy="0" izz="0" ixy="0" ixz="0" iyz="0"/>
      <origin xyz="-1.7363871e-18 -0.024987802 0.031234752" rpy="0 0 0"/>
    </inertial>
  </link>
  <joint name="Fastened_2" type="fixed">
    <origin xyz="-1.9306432e-07 0.01527796 -0.021835193" rpy="0.67474094 0 0"/>
    <parent link="bottomshell_1"/>
    <child link="topshell_1"/>
  </joint>
  <joint name="Revolute_1" type="revolute">
    <origin xyz="-1.9306432e-07 -0.02472204 -0.021835193" rpy="-2.2455373 0 0"/>
    <parent link="bottomshell_1"/>
    <child link="pendulum_1"/>
    <axis xyz="0 0 -1"/>
    <limit effort="1" velocity="1" lower="-6.2831853" upper="6.2831853"/>
  </joint>
</robot>
