<?xml version="1.0" ?>
<robot name="balo">
  <link name="shell_1">
    <visual name="shell_1_visual">
      <origin xyz="0 0 0" rpy="0 0 0"/>
      <geometry>
        <mesh filename="meshes/shell_1.stl"/>
      </geometry>
      <material name="shell_1-material">
        <color rgba="0 1 0 0.3"/>
      </material>
    </visual>
    <collision name="shell_1_collision">
      <origin xyz="0 0 0" rpy="0 0 0"/>
      <geometry>
        <mesh filename="meshes/shell_1.stl"/>
      </geometry>
    </collision>
    <inertial>
      <mass value="0.088985938"/>
      <inertia ixx="0.00016876671" iyy="0.00016410772" izz="0.00014336465" ixy="5.1142179e-09" ixz="-5.2051475e-09" iyz="-4.8349282e-06"/>
      <origin xyz="0 0 0" rpy="0 0 0"/>
    </inertial>
  </link>
  <link name="pendulum_1">
    <visual name="pendulum_1_visual">
      <origin xyz="0 0 0" rpy="0 0 0"/>
      <geometry>
        <mesh filename="meshes/pendulum_1.stl"/>
      </geometry>
      <material name="pendulum_1-material">
        <color rgba="1 0 0 1"/>
      </material>
    </visual>
    <!-- <collision name="pendulum_1_collision">
      <origin xyz="0 0 0" rpy="0 0 0"/>
      <geometry>
        <mesh filename="meshes/pendulum_1.stl"/>
      </geometry>
    </collision> -->
    <inertial>
      <mass value="0.025374834"/>
      <inertia ixx="1.1946991e-06" iyy="6.269065e-07" izz="1.1979902e-06" ixy="4.3353096e-08" ixz="-8.6023829e-25" iyz="8.4595407e-23"/>
      <origin xyz="-0.0027313234 0.035979304 0" rpy="0 0 0"/>
    </inertial>
  </link>
  <joint name="Revolute_1" type="revolute">
    <origin xyz="1.022949e-05 -1.6753779e-06 9.9866003e-06" rpy="3.1415927 0 0"/>
    <parent link="shell_1"/>
    <child link="pendulum_1"/>
    <axis xyz="0 0 -1"/>
    <limit effort="1" velocity="1" lower="-6.2831853" upper="6.2831853"/>
  </joint>
</robot>
