<?xml version="1.0" ?>
<robot name="pmrock">
  <link name="foot_1">
    <visual name="foot_1_visual">
      <origin xyz="0 0 0" rpy="0 0 0"/>
      <geometry>
        <mesh filename="meshes/foot_1.stl"/>
      </geometry>
      <material name="foot_1-material">
        <color rgba="0 0 0 1"/>
      </material>
    </visual>
    <collision name="foot_1_collision">
      <origin xyz="0 0 0" rpy="0 0 0"/>
      <geometry>
        <mesh filename="meshes/foot_1.stl"/>
      </geometry>
    </collision>
    <inertial>
      <mass value="0.011393509"/>
      <inertia ixx="4.5574037e-07" iyy="4.5574037e-07" izz="4.5574037e-07" ixy="0" ixz="0" iyz="0"/>
      <origin xyz="0 0 0" rpy="0 0 0"/>
    </inertial>
  </link>
  <link name="pendulum_1">
    <visual name="pendulum_1_visual">
      <origin xyz="0 0 0" rpy="0 0 0"/>
      <geometry>
        <mesh filename="meshes/pendulum_1.stl"/>
      </geometry>
      <material name="pendulum_1-material">
        <color rgba="1 0 0 1"/>
      </material>
    </visual>
    <!-- <collision name="pendulum_1_collision">
      <origin xyz="0 0 0" rpy="0 0 0"/>
      <geometry>
        <mesh filename="meshes/pendulum_1.stl"/>
      </geometry>
    </collision> -->
    <inertial>
      <mass value="0.150"/>
      <inertia ixx="6.0770112e-06" iyy="1.8067333e-05" izz="1.8067333e-05" ixy="0" ixz="0" iyz="0"/>
      <origin xyz="-0.056818182 0 -0.002" rpy="0 0 0"/>
    </inertial>
  </link>
  <link name="shell_com_1">
    <visual name="shell_com_1_visual">
      <origin xyz="0 0 0" rpy="0 0 0"/>
      <geometry>
        <mesh filename="meshes/shell_com_1.stl"/>
      </geometry>
      <material name="shell_com_1-material">
        <color rgba="0 0 0 0.3"/>
      </material>
    </visual>
    <!-- <collision name="shell_com_1_collision">
      <origin xyz="0 0 0" rpy="0 0 0"/>
      <geometry>
        <mesh filename="meshes/shell_com_1.stl"/>
      </geometry>
    </collision> -->
    <inertial>
      <mass value="0.100"/>
      <inertia ixx="0.0023358" iyy="0.0023358" izz="0.00459" ixy="0" ixz="0" iyz="0"/>
      <origin xyz="1.9081958e-17 -1.8822954e-18 -0.01" rpy="0 0 0"/>
    </inertial>
  </link>
  <joint name="Revolute_1" type="revolute">
    <origin xyz="0.002 0 0.148" rpy="3.1415927 0 0"/>
    <parent link="foot_1"/>
    <child link="pendulum_1"/>
    <axis xyz="0 0 -1"/>
    <limit effort="1" velocity="1" lower="-6.2831853" upper="6.2831853"/>
  </joint>
  <joint name="Fastened_1" type="fixed">
    <origin xyz="0.002 0 0.115" rpy="3.1415927 0 0"/>
    <parent link="foot_1"/>
    <child link="shell_com_1"/>
  </joint>
</robot>
