<?xml version="1.0" ?>
<robot name="balo_2">
  <link name="shell1_1">
    <visual name="shell1_1_visual">
      <origin xyz="0 0 0" rpy="0 0 0"/>
      <geometry>
        <mesh filename="meshes/shell1_1.stl"/>
      </geometry>
      <material name="shell1_1-material">
        <color rgba="0 1 0 0.3"/>
      </material>
    </visual>
    <collision name="shell1_1_collision">
      <origin xyz="0 0 0" rpy="0 0 0"/>
      <geometry>
        <mesh filename="meshes/shell1_1.stl"/>
      </geometry>
    </collision>
    <inertial>
      <mass value="0.046789112"/>
      <inertia ixx="3.4602215e-05" iyy="6.0137625e-05" izz="3.888731e-05" ixy="1.2826811e-11" ixz="-1.2145494e-09" iyz="5.5327885e-12"/>
      <origin xyz="0 0 0" rpy="0 0 0"/>
    </inertial>
  </link>
  <link name="pendulum_1">
    <visual name="pendulum_1_visual">
      <origin xyz="0 0 0" rpy="0 0 0"/>
      <geometry>
        <mesh filename="meshes/pendulum_1.stl"/>
      </geometry>
      <material name="pendulum_1-material">
        <color rgba="1 1 1 1"/>
      </material>
    </visual>
    <collision name="pendulum_1_collision">
      <origin xyz="0 0 0" rpy="0 0 0"/>
      <geometry>
        <mesh filename="meshes/pendulum_1.stl"/>
      </geometry>
    </collision>
    <inertial>
      <mass value="0.0090925339"/>
      <inertia ixx="6.5245276e-08" iyy="7.3991477e-07" izz="7.6727449e-07" ixy="0" ixz="0" iyz="0"/>
      <origin xyz="0.019850709 7.9725511e-20 -6.4528717e-20" rpy="0 0 0"/>
    </inertial>
  </link>
  <link name="shell2_1">
    <visual name="shell2_1_visual">
      <origin xyz="0 0 0" rpy="0 0 0"/>
      <geometry>
        <mesh filename="meshes/shell2_1.stl"/>
      </geometry>
      <material name="shell2_1-material">
        <color rgba="1 0 0.5 0.3"/>
      </material>
    </visual>
    <collision name="shell2_1_collision">
      <origin xyz="0 0 0" rpy="0 0 0"/>
      <geometry>
        <mesh filename="meshes/shell2_1.stl"/>
      </geometry>
    </collision>
    <inertial>
      <mass value="0.046786181"/>
      <inertia ixx="3.4600579e-05" iyy="3.8885939e-05" izz="6.0134636e-05" ixy="1.6644634e-09" ixz="1.2692009e-14" iyz="2.6485869e-14"/>
      <origin xyz="-3.5314187e-11 -6.914444e-11 -0.021814721" rpy="0 0 0"/>
    </inertial>
  </link>
  <joint name="Revolute_1" type="revolute">
    <origin xyz="-3.8094256e-09 -0.021814691 -7.5655039e-10" rpy="-1.5707963 0 0"/>
    <parent link="shell1_1"/>
    <child link="pendulum_1"/>
    <axis xyz="0 0 -1"/>
    <limit effort="1" velocity="1" lower="-6.2831853" upper="6.2831853"/>
  </joint>
  <joint name="Fastened_1" type="fixed">
    <origin xyz="-3.8094256e-09 -0.021814691 -7.5655039e-10" rpy="-1.5707963 0 0"/>
    <parent link="shell1_1"/>
    <child link="shell2_1"/>
  </joint>
</robot>
